<?xml version="1.0"?>
<robot xmlns:xacro="http://www.ros.org/wiki/xacro">

    <xacro:include filename="inertial_macros.xacro"/>
    
    <material name="grey">
        <color rgba="0.7 0.7 0.7 1.0"/>
    </material>

    <material name="black">
        <color rgba="0 0 0 1.0"/>
    </material>

    <material name="green">
        <color rgba="0 0.6 0 1.0"/>
    </material>

    <material name="blue">
        <color rgba="0 0.0 0.7 1.0"/>
    </material>

    <material name="red">
        <color rgba="0.6 0.0 0 1.0"/>
    </material>

    <material name="white">
        <color rgba="1 1 1 1.0"/>
    </material>

    <!-- BASE LINK -->

    <link name="base_link">
    </link>
    <!-- CHASSIS LINK -->
    <link name="chassis_link">
        <visual>
            <geometry>
                <box size="0.6 0.4 0.2"/>
            </geometry>
            <origin xyz="0.3 0.0 0.1" rpy="0.0 0.0 0.0"/>
            <material name="grey"/>
        </visual>
        <collision>
            <geometry>
                <box size="0.6 0.4 0.2"/>
            </geometry>
            <origin xyz="0.3 0.0 0.1" rpy="0.0 0.0 0.0"/>
        </collision>
        <xacro:inertial_box mass="0.75" x="0.6" y="0.4" z="0.2">
            <origin xyz="0.3 0.0 0.1" rpy="0.0 0.0 0.0"/>
        </xacro:inertial_box>
    </link>
    <gazebo reference="chassis_link">
        <mu1>0.2</mu1>
        <mu2>0.2</mu2>
        <material>Gazebo/Grey</material>
    </gazebo>
    <joint name="chassis_joint" type="fixed">
        <parent link="base_link"/>
        <child link="chassis_link"/>
        <origin xyz="-0.1 0.0 0.0" rpy="0.0 0.0 0.0"/>
    </joint>
    <!-- LEFT WHEEL(BACK)-->
    <link name="left_back_wheel">
        <visual>
            <origin xyz="0.0 0.0 0.0" rpy="0.0 0.0 0.0"/>
            <geometry>
                <cylinder radius="0.1" length="0.05"/>
            </geometry>
            <material name="black"/>
        </visual>
        <collision>
            <origin xyz="0.0 0.0 0.0" rpy="0.0 0.0 0.0"/>
            <geometry>
                <cylinder radius="0.1" length="0.05"/>
            </geometry>
        </collision>
        <xacro:inertial_cylinder mass="0.2" radius="0.1" length="0.05">
            <origin xyz="0.0 0.0 0.0" rpy="0.0 0.0 0.0"/>
        </xacro:inertial_cylinder>
    </link>
    <gazebo reference="left_back_wheel">
        <mu1>0.2</mu1>
        <mu2>0.2</mu2>
        <material>Gazebo/Black</material>
    </gazebo>
    <joint name="left_back_wheel_joint" type="continuous">
        <origin xyz="0.0 0.225 0.0" rpy="-1.5707963267948966 0.0 0.0"/>
        <parent link="base_link"/>
        <child link="left_back_wheel"/>
        <axis xyz="0.0 0.0 1.0"/>
    </joint>

    <!-- RIGHT WHEEL(BACK)-->
    <link name="right_back_wheel">
        <visual>
            <origin xyz="0.0 0.0 0.0" rpy="0.0 0.0 0.0"/>
            <geometry>
                <cylinder radius="0.1" length="0.05"/>
            </geometry>
            <material name="black"/>
        </visual>
        <collision>
            <origin xyz="0.0 0.0 0.0" rpy="0.0 0.0 0.0"/>
            <geometry>
                <cylinder radius="0.1" length="0.05"/>
            </geometry>
        </collision>
        <xacro:inertial_cylinder mass="0.2" radius="0.1" length="0.05">
            <origin xyz="0.0 0.0 0.0" rpy="0.0 0.0 0.0"/>
        </xacro:inertial_cylinder>
    </link>
    <gazebo reference="right_back_wheel">
        <mu1>0.2</mu1>
        <mu2>0.2</mu2>
        <material>Gazebo/Black</material>
    </gazebo>
    <joint name="right_back_wheel_joint" type="continuous">
        <origin xyz="0.0 -0.225 0.0" rpy="1.5707963267948966 0.0 0.0"/>
        <parent link="base_link"/>
        <child link="right_back_wheel"/>
        <axis xyz="0.0 0.0 -1.0"/>
    </joint>
    <!-- LEFT WHEEL(FRONT)-->
    <link name="left_front_wheel">
        <visual>
            <origin xyz="0.0 0.0 0.0" rpy="0.0 0.0 0.0"/>
            <geometry>
                <cylinder radius="0.1" length="0.05"/>
            </geometry>
            <material name="black"/>
        </visual>
        <collision>
            <origin xyz="0.0 0.0 0.0" rpy="0.0 0.0 0.0"/>
            <geometry>
                <cylinder radius="0.1" length="0.05"/>
            </geometry>
        </collision>
        <xacro:inertial_cylinder mass="0.2" radius="0.1" length="0.05">
            <origin xyz="0.0 0.0 0.0" rpy="0.0 0.0 0.0"/>
        </xacro:inertial_cylinder>
    </link>
    <gazebo reference="left_front_wheel">
        <mu1>0.2</mu1>
        <mu2>0.2</mu2>
        <material>Gazebo/Black</material>
    </gazebo>
    <joint name="left_front_wheel_joint" type="continuous">
        <origin xyz="0.4 0.225 0.0" rpy="-1.5707963267948966 0.0 0.0"/>
        <parent link="base_link"/>
        <child link="left_front_wheel"/>
        <axis xyz="0.0 0.0 1.0"/>
    </joint>

    <!-- RIGHT WHEEL(FRONT)-->
    <link name="right_front_wheel">
        <visual>
            <origin xyz="0.0 0.0 0.0" rpy="0.0 0.0 0.0"/>
            <geometry>
                <cylinder radius="0.1" length="0.05"/>
            </geometry>
            <material name="black"/>
        </visual>
        <collision>
            <origin xyz="0.0 0.0 0.0" rpy="0.0 0.0 0.0"/>
            <geometry>
                <cylinder radius="0.1" length="0.05"/>
            </geometry>
        </collision>
        <xacro:inertial_cylinder mass="0.2" radius="0.1" length="0.05">
            <origin xyz="0.0 0.0 0.0" rpy="0.0 0.0 0.0"/>
        </xacro:inertial_cylinder>
    </link>
    <gazebo reference="right_front_wheel">
        <mu1>0.2</mu1>
        <mu2>0.2</mu2>
        <material>Gazebo/Black</material>
    </gazebo>
    <joint name="right_front_wheel_joint" type="continuous">
        <origin xyz="0.4 -0.225 0.0" rpy="1.5707963267948966 0.0 0.0"/>
        <parent link="base_link"/>
        <child link="right_front_wheel"/>
        <axis xyz="0.0 0.0 -1.0"/>
    </joint>
</robot>
